[19/Mar/2015 09:59:00] DEBUG [django.db.backends:91] (0.000) SET SQL_AUTO_IS_NULL = 0; args=None
[19/Mar/2015 09:59:00] DEBUG [django.db.backends:91] (0.000) SHOW TABLES; args=None
[19/Mar/2015 09:59:00] DEBUG [django.db.backends:91] (0.000) SELECT `django_migrations`.`app`, `django_migrations`.`name` FROM `django_migrations`; args=()
[19/Mar/2015 09:59:10] WARNING [django.request:143] Not Found: /home2/css/style.css
[19/Mar/2015 09:59:12] WARNING [django.request:143] Not Found: /home2/css/style.css
[19/Mar/2015 09:59:18] WARNING [django.request:143] Not Found: /home2/css/style.css
[19/Mar/2015 09:59:36] WARNING [django.request:143] Not Found: /home2/css/style.css
[19/Mar/2015 09:59:38] WARNING [django.request:143] Not Found: /home2/css/style.css
[19/Mar/2015 09:59:41] WARNING [django.request:143] Not Found: /home2/css/style.css
[19/Mar/2015 09:59:50] WARNING [django.request:143] Not Found: /home2/css/style.css
[19/Mar/2015 10:01:04] WARNING [django.request:143] Not Found: /home2/css/style.css
[19/Mar/2015 10:01:27] DEBUG [django.db.backends:91] (0.000) SET SQL_AUTO_IS_NULL = 0; args=None
[19/Mar/2015 10:01:27] DEBUG [django.db.backends:91] (0.000) SHOW TABLES; args=None
[19/Mar/2015 10:01:27] DEBUG [django.db.backends:91] (0.000) SELECT `django_migrations`.`app`, `django_migrations`.`name` FROM `django_migrations`; args=()
[19/Mar/2015 10:01:27] WARNING [django.request:143] Not Found: /home2/css/style.css
[19/Mar/2015 10:02:02] DEBUG [django.db.backends:91] (0.000) SET SQL_AUTO_IS_NULL = 0; args=None
[19/Mar/2015 10:02:02] DEBUG [django.db.backends:91] (0.000) SHOW TABLES; args=None
[19/Mar/2015 10:02:02] DEBUG [django.db.backends:91] (0.000) SELECT `django_migrations`.`app`, `django_migrations`.`name` FROM `django_migrations`; args=()
[19/Mar/2015 10:02:03] ERROR [django.request:231] Internal Server Error: /home2/
Traceback (most recent call last):
  File "/Users/jcook/.virtualenvs/default/lib/python2.7/site-packages/django/core/handlers/base.py", line 111, in get_response
    response = wrapped_callback(request, *callback_args, **callback_kwargs)
  File "/Users/jcook/Repos/site3/game/views.py", line 25, in home2
    return render(request, template, {'room'})
  File "/Users/jcook/.virtualenvs/default/lib/python2.7/site-packages/django/shortcuts.py", line 50, in render
    return HttpResponse(loader.render_to_string(*args, **kwargs),
  File "/Users/jcook/.virtualenvs/default/lib/python2.7/site-packages/django/template/loader.py", line 177, in render_to_string
    with context_instance.push(dictionary):
  File "/Users/jcook/.virtualenvs/default/lib/python2.7/site-packages/django/template/context.py", line 54, in push
    return ContextDict(self, *args, **kwargs)
  File "/Users/jcook/.virtualenvs/default/lib/python2.7/site-packages/django/template/context.py", line 19, in __init__
    super(ContextDict, self).__init__(*args, **kwargs)
ValueError: dictionary update sequence element #0 has length 4; 2 is required
[19/Mar/2015 10:03:52] DEBUG [django.db.backends:91] (0.000) SET SQL_AUTO_IS_NULL = 0; args=None
[19/Mar/2015 10:03:52] DEBUG [django.db.backends:91] (0.000) SHOW TABLES; args=None
[19/Mar/2015 10:03:52] DEBUG [django.db.backends:91] (0.000) SELECT `django_migrations`.`app`, `django_migrations`.`name` FROM `django_migrations`; args=()
[19/Mar/2015 10:03:53] ERROR [django.request:231] Internal Server Error: /home2/
Traceback (most recent call last):
  File "/Users/jcook/.virtualenvs/default/lib/python2.7/site-packages/django/core/handlers/base.py", line 111, in get_response
    response = wrapped_callback(request, *callback_args, **callback_kwargs)
  File "/Users/jcook/Repos/site3/game/views.py", line 25, in home2
    return render(request, template, {'room.name'})
  File "/Users/jcook/.virtualenvs/default/lib/python2.7/site-packages/django/shortcuts.py", line 50, in render
    return HttpResponse(loader.render_to_string(*args, **kwargs),
  File "/Users/jcook/.virtualenvs/default/lib/python2.7/site-packages/django/template/loader.py", line 177, in render_to_string
    with context_instance.push(dictionary):
  File "/Users/jcook/.virtualenvs/default/lib/python2.7/site-packages/django/template/context.py", line 54, in push
    return ContextDict(self, *args, **kwargs)
  File "/Users/jcook/.virtualenvs/default/lib/python2.7/site-packages/django/template/context.py", line 19, in __init__
    super(ContextDict, self).__init__(*args, **kwargs)
ValueError: dictionary update sequence element #0 has length 9; 2 is required
[19/Mar/2015 10:04:44] DEBUG [django.db.backends:91] (0.000) SET SQL_AUTO_IS_NULL = 0; args=None
[19/Mar/2015 10:04:44] DEBUG [django.db.backends:91] (0.000) SHOW TABLES; args=None
[19/Mar/2015 10:04:44] DEBUG [django.db.backends:91] (0.000) SELECT `django_migrations`.`app`, `django_migrations`.`name` FROM `django_migrations`; args=()
[19/Mar/2015 10:04:45] ERROR [django.request:231] Internal Server Error: /home2/
Traceback (most recent call last):
  File "/Users/jcook/.virtualenvs/default/lib/python2.7/site-packages/django/core/handlers/base.py", line 111, in get_response
    response = wrapped_callback(request, *callback_args, **callback_kwargs)
  File "/Users/jcook/Repos/site3/game/views.py", line 25, in home2
    return render(request, template, {'room.name, room.description, room.exits, room.items'})
  File "/Users/jcook/.virtualenvs/default/lib/python2.7/site-packages/django/shortcuts.py", line 50, in render
    return HttpResponse(loader.render_to_string(*args, **kwargs),
  File "/Users/jcook/.virtualenvs/default/lib/python2.7/site-packages/django/template/loader.py", line 177, in render_to_string
    with context_instance.push(dictionary):
  File "/Users/jcook/.virtualenvs/default/lib/python2.7/site-packages/django/template/context.py", line 54, in push
    return ContextDict(self, *args, **kwargs)
  File "/Users/jcook/.virtualenvs/default/lib/python2.7/site-packages/django/template/context.py", line 19, in __init__
    super(ContextDict, self).__init__(*args, **kwargs)
ValueError: dictionary update sequence element #0 has length 51; 2 is required
[19/Mar/2015 10:05:39] ERROR [django.request:231] Internal Server Error: /home2/
Traceback (most recent call last):
  File "/Users/jcook/.virtualenvs/default/lib/python2.7/site-packages/django/core/handlers/base.py", line 111, in get_response
    response = wrapped_callback(request, *callback_args, **callback_kwargs)
  File "/Users/jcook/Repos/site3/game/views.py", line 25, in home2
    return render(request, template, {'room.name, room.description, room.exits, room.items'})
  File "/Users/jcook/.virtualenvs/default/lib/python2.7/site-packages/django/shortcuts.py", line 50, in render
    return HttpResponse(loader.render_to_string(*args, **kwargs),
  File "/Users/jcook/.virtualenvs/default/lib/python2.7/site-packages/django/template/loader.py", line 177, in render_to_string
    with context_instance.push(dictionary):
  File "/Users/jcook/.virtualenvs/default/lib/python2.7/site-packages/django/template/context.py", line 54, in push
    return ContextDict(self, *args, **kwargs)
  File "/Users/jcook/.virtualenvs/default/lib/python2.7/site-packages/django/template/context.py", line 19, in __init__
    super(ContextDict, self).__init__(*args, **kwargs)
ValueError: dictionary update sequence element #0 has length 51; 2 is required
[19/Mar/2015 10:05:46] ERROR [django.request:231] Internal Server Error: /home2/
Traceback (most recent call last):
  File "/Users/jcook/.virtualenvs/default/lib/python2.7/site-packages/django/core/handlers/base.py", line 111, in get_response
    response = wrapped_callback(request, *callback_args, **callback_kwargs)
  File "/Users/jcook/Repos/site3/game/views.py", line 25, in home2
    return render(request, template, {'name', 'description', 'exits', 'items'})
  File "/Users/jcook/.virtualenvs/default/lib/python2.7/site-packages/django/shortcuts.py", line 50, in render
    return HttpResponse(loader.render_to_string(*args, **kwargs),
  File "/Users/jcook/.virtualenvs/default/lib/python2.7/site-packages/django/template/loader.py", line 177, in render_to_string
    with context_instance.push(dictionary):
  File "/Users/jcook/.virtualenvs/default/lib/python2.7/site-packages/django/template/context.py", line 54, in push
    return ContextDict(self, *args, **kwargs)
  File "/Users/jcook/.virtualenvs/default/lib/python2.7/site-packages/django/template/context.py", line 19, in __init__
    super(ContextDict, self).__init__(*args, **kwargs)
ValueError: dictionary update sequence element #0 has length 51; 2 is required
[19/Mar/2015 10:05:46] DEBUG [django.db.backends:91] (0.000) SET SQL_AUTO_IS_NULL = 0; args=None
[19/Mar/2015 10:05:46] DEBUG [django.db.backends:91] (0.000) SHOW TABLES; args=None
[19/Mar/2015 10:05:46] DEBUG [django.db.backends:91] (0.000) SELECT `django_migrations`.`app`, `django_migrations`.`name` FROM `django_migrations`; args=()
[19/Mar/2015 10:06:52] ERROR [django.request:231] Internal Server Error: /home2/
Traceback (most recent call last):
  File "/Users/jcook/.virtualenvs/default/lib/python2.7/site-packages/django/core/handlers/base.py", line 111, in get_response
    response = wrapped_callback(request, *callback_args, **callback_kwargs)
  File "/Users/jcook/Repos/site3/game/views.py", line 25, in home2
    return render(request, template, {'name'}, {'description'}, {'exits'}, {'items'})
  File "/Users/jcook/.virtualenvs/default/lib/python2.7/site-packages/django/shortcuts.py", line 50, in render
    return HttpResponse(loader.render_to_string(*args, **kwargs),
TypeError: render_to_string() takes at most 4 arguments (6 given)
[19/Mar/2015 10:07:29] DEBUG [django.db.backends:91] (0.000) SET SQL_AUTO_IS_NULL = 0; args=None
[19/Mar/2015 10:07:29] DEBUG [django.db.backends:91] (0.000) SHOW TABLES; args=None
[19/Mar/2015 10:07:29] DEBUG [django.db.backends:91] (0.000) SELECT `django_migrations`.`app`, `django_migrations`.`name` FROM `django_migrations`; args=()
[19/Mar/2015 10:08:03] ERROR [django.request:231] Internal Server Error: /home2/
Traceback (most recent call last):
  File "/Users/jcook/.virtualenvs/default/lib/python2.7/site-packages/django/core/handlers/base.py", line 111, in get_response
    response = wrapped_callback(request, *callback_args, **callback_kwargs)
  File "/Users/jcook/Repos/site3/game/views.py", line 25, in home2
    return render(request, template, {'name'})
  File "/Users/jcook/.virtualenvs/default/lib/python2.7/site-packages/django/shortcuts.py", line 50, in render
    return HttpResponse(loader.render_to_string(*args, **kwargs),
  File "/Users/jcook/.virtualenvs/default/lib/python2.7/site-packages/django/template/loader.py", line 177, in render_to_string
    with context_instance.push(dictionary):
  File "/Users/jcook/.virtualenvs/default/lib/python2.7/site-packages/django/template/context.py", line 54, in push
    return ContextDict(self, *args, **kwargs)
  File "/Users/jcook/.virtualenvs/default/lib/python2.7/site-packages/django/template/context.py", line 19, in __init__
    super(ContextDict, self).__init__(*args, **kwargs)
ValueError: dictionary update sequence element #0 has length 4; 2 is required
[19/Mar/2015 10:09:21] ERROR [django.request:231] Internal Server Error: /home2/
Traceback (most recent call last):
  File "/Users/jcook/.virtualenvs/default/lib/python2.7/site-packages/django/core/handlers/base.py", line 111, in get_response
    response = wrapped_callback(request, *callback_args, **callback_kwargs)
  File "/Users/jcook/Repos/site3/game/views.py", line 25, in home2
    return render(request, template, {'name'})
  File "/Users/jcook/.virtualenvs/default/lib/python2.7/site-packages/django/shortcuts.py", line 50, in render
    return HttpResponse(loader.render_to_string(*args, **kwargs),
  File "/Users/jcook/.virtualenvs/default/lib/python2.7/site-packages/django/template/loader.py", line 177, in render_to_string
    with context_instance.push(dictionary):
  File "/Users/jcook/.virtualenvs/default/lib/python2.7/site-packages/django/template/context.py", line 54, in push
    return ContextDict(self, *args, **kwargs)
  File "/Users/jcook/.virtualenvs/default/lib/python2.7/site-packages/django/template/context.py", line 19, in __init__
    super(ContextDict, self).__init__(*args, **kwargs)
ValueError: dictionary update sequence element #0 has length 4; 2 is required
[19/Mar/2015 10:13:15] DEBUG [django.db.backends:91] (0.000) SET SQL_AUTO_IS_NULL = 0; args=None
[19/Mar/2015 10:13:15] DEBUG [django.db.backends:91] (0.000) SHOW TABLES; args=None
[19/Mar/2015 10:13:15] DEBUG [django.db.backends:91] (0.000) SELECT `django_migrations`.`app`, `django_migrations`.`name` FROM `django_migrations`; args=()
[19/Mar/2015 10:13:18] ERROR [django.request:231] Internal Server Error: /home2/
Traceback (most recent call last):
  File "/Users/jcook/.virtualenvs/default/lib/python2.7/site-packages/django/core/handlers/base.py", line 111, in get_response
    response = wrapped_callback(request, *callback_args, **callback_kwargs)
  File "/Users/jcook/Repos/site3/game/views.py", line 25, in home2
    return render(request, rpg/home2.html, context)
NameError: global name 'rpg' is not defined
[19/Mar/2015 10:13:18] DEBUG [django.db.backends:91] (0.000) SET SQL_AUTO_IS_NULL = 0; args=None
[19/Mar/2015 10:13:18] DEBUG [django.db.backends:91] (0.000) SELECT `rpg_room`.`id`, `rpg_room`.`name`, `rpg_room`.`description`, `rpg_room`.`neighbors`, `rpg_room`.`exits`, `rpg_room`.`items` FROM `rpg_room` LIMIT 21; args=()
[19/Mar/2015 10:13:18] DEBUG [django.db.backends:91] (0.000) SELECT `rpg_room`.`id`, `rpg_room`.`name`, `rpg_room`.`description`, `rpg_room`.`neighbors`, `rpg_room`.`exits`, `rpg_room`.`items` FROM `rpg_room` LIMIT 21; args=()
[19/Mar/2015 10:13:18] DEBUG [django.db.backends:91] (0.000) SELECT `rpg_room`.`id`, `rpg_room`.`name`, `rpg_room`.`description`, `rpg_room`.`neighbors`, `rpg_room`.`exits`, `rpg_room`.`items` FROM `rpg_room` LIMIT 21; args=()
[19/Mar/2015 10:14:01] DEBUG [django.db.backends:91] (0.000) SET SQL_AUTO_IS_NULL = 0; args=None
[19/Mar/2015 10:14:01] DEBUG [django.db.backends:91] (0.000) SHOW TABLES; args=None
[19/Mar/2015 10:14:01] DEBUG [django.db.backends:91] (0.000) SELECT `django_migrations`.`app`, `django_migrations`.`name` FROM `django_migrations`; args=()
[19/Mar/2015 10:14:01] ERROR [django.request:231] Internal Server Error: /home2/
Traceback (most recent call last):
  File "/Users/jcook/.virtualenvs/default/lib/python2.7/site-packages/django/core/handlers/base.py", line 111, in get_response
    response = wrapped_callback(request, *callback_args, **callback_kwargs)
  File "/Users/jcook/Repos/site3/game/views.py", line 25, in home2
    return render(request, home2.html, context)
AttributeError: 'function' object has no attribute 'html'
[19/Mar/2015 10:14:01] DEBUG [django.db.backends:91] (0.000) SET SQL_AUTO_IS_NULL = 0; args=None
[19/Mar/2015 10:14:01] DEBUG [django.db.backends:91] (0.000) SELECT `rpg_room`.`id`, `rpg_room`.`name`, `rpg_room`.`description`, `rpg_room`.`neighbors`, `rpg_room`.`exits`, `rpg_room`.`items` FROM `rpg_room` LIMIT 21; args=()
[19/Mar/2015 10:14:01] DEBUG [django.db.backends:91] (0.000) SELECT `rpg_room`.`id`, `rpg_room`.`name`, `rpg_room`.`description`, `rpg_room`.`neighbors`, `rpg_room`.`exits`, `rpg_room`.`items` FROM `rpg_room` LIMIT 21; args=()
[19/Mar/2015 10:14:01] DEBUG [django.db.backends:91] (0.000) SELECT `rpg_room`.`id`, `rpg_room`.`name`, `rpg_room`.`description`, `rpg_room`.`neighbors`, `rpg_room`.`exits`, `rpg_room`.`items` FROM `rpg_room` LIMIT 21; args=()
[19/Mar/2015 10:14:37] ERROR [django.request:231] Internal Server Error: /home2/
Traceback (most recent call last):
  File "/Users/jcook/.virtualenvs/default/lib/python2.7/site-packages/django/core/handlers/base.py", line 111, in get_response
    response = wrapped_callback(request, *callback_args, **callback_kwargs)
  File "/Users/jcook/Repos/site3/game/views.py", line 25, in home2
    return render(request, home2.html, context)
AttributeError: 'function' object has no attribute 'html'
[19/Mar/2015 10:14:37] DEBUG [django.db.backends:91] (0.000) SET SQL_AUTO_IS_NULL = 0; args=None
[19/Mar/2015 10:14:37] DEBUG [django.db.backends:91] (0.000) SELECT `rpg_room`.`id`, `rpg_room`.`name`, `rpg_room`.`description`, `rpg_room`.`neighbors`, `rpg_room`.`exits`, `rpg_room`.`items` FROM `rpg_room` LIMIT 21; args=()
[19/Mar/2015 10:14:37] DEBUG [django.db.backends:91] (0.001) SELECT `rpg_room`.`id`, `rpg_room`.`name`, `rpg_room`.`description`, `rpg_room`.`neighbors`, `rpg_room`.`exits`, `rpg_room`.`items` FROM `rpg_room` LIMIT 21; args=()
[19/Mar/2015 10:14:37] DEBUG [django.db.backends:91] (0.000) SELECT `rpg_room`.`id`, `rpg_room`.`name`, `rpg_room`.`description`, `rpg_room`.`neighbors`, `rpg_room`.`exits`, `rpg_room`.`items` FROM `rpg_room` LIMIT 21; args=()
[19/Mar/2015 10:14:39] DEBUG [django.db.backends:91] (0.000) SET SQL_AUTO_IS_NULL = 0; args=None
[19/Mar/2015 10:14:39] DEBUG [django.db.backends:91] (0.001) SHOW TABLES; args=None
[19/Mar/2015 10:14:39] DEBUG [django.db.backends:91] (0.001) SELECT `django_migrations`.`app`, `django_migrations`.`name` FROM `django_migrations`; args=()
[19/Mar/2015 10:16:39] ERROR [django.request:231] Internal Server Error: /home2/
Traceback (most recent call last):
  File "/Users/jcook/.virtualenvs/default/lib/python2.7/site-packages/django/core/handlers/base.py", line 111, in get_response
    response = wrapped_callback(request, *callback_args, **callback_kwargs)
  File "/Users/jcook/Repos/site3/game/views.py", line 25, in home2
    return render(request, home2, context)
  File "/Users/jcook/.virtualenvs/default/lib/python2.7/site-packages/django/shortcuts.py", line 50, in render
    return HttpResponse(loader.render_to_string(*args, **kwargs),
  File "/Users/jcook/.virtualenvs/default/lib/python2.7/site-packages/django/template/loader.py", line 170, in render_to_string
    t = get_template(template_name, dirs)
  File "/Users/jcook/.virtualenvs/default/lib/python2.7/site-packages/django/template/loader.py", line 144, in get_template
    template, origin = find_template(template_name, dirs)
  File "/Users/jcook/.virtualenvs/default/lib/python2.7/site-packages/django/template/loader.py", line 136, in find_template
    raise TemplateDoesNotExist(name)
TemplateDoesNotExist: <function home2 at 0x10d166a28>
[19/Mar/2015 10:16:39] DEBUG [django.db.backends:91] (0.000) SET SQL_AUTO_IS_NULL = 0; args=None
[19/Mar/2015 10:16:39] DEBUG [django.db.backends:91] (0.000) SELECT `rpg_room`.`id`, `rpg_room`.`name`, `rpg_room`.`description`, `rpg_room`.`neighbors`, `rpg_room`.`exits`, `rpg_room`.`items` FROM `rpg_room` LIMIT 21; args=()
[19/Mar/2015 10:16:39] DEBUG [django.db.backends:91] (0.000) SELECT `rpg_room`.`id`, `rpg_room`.`name`, `rpg_room`.`description`, `rpg_room`.`neighbors`, `rpg_room`.`exits`, `rpg_room`.`items` FROM `rpg_room` LIMIT 21; args=()
[19/Mar/2015 10:16:39] DEBUG [django.db.backends:91] (0.000) SELECT `rpg_room`.`id`, `rpg_room`.`name`, `rpg_room`.`description`, `rpg_room`.`neighbors`, `rpg_room`.`exits`, `rpg_room`.`items` FROM `rpg_room` LIMIT 21; args=()
[19/Mar/2015 10:16:39] DEBUG [django.db.backends:91] (0.000) SELECT `rpg_room`.`id`, `rpg_room`.`name`, `rpg_room`.`description`, `rpg_room`.`neighbors`, `rpg_room`.`exits`, `rpg_room`.`items` FROM `rpg_room` LIMIT 21; args=()
[19/Mar/2015 10:16:39] DEBUG [django.db.backends:91] (0.000) SELECT `rpg_room`.`id`, `rpg_room`.`name`, `rpg_room`.`description`, `rpg_room`.`neighbors`, `rpg_room`.`exits`, `rpg_room`.`items` FROM `rpg_room` LIMIT 21; args=()
[19/Mar/2015 10:16:39] DEBUG [django.db.backends:91] (0.000) SELECT `rpg_room`.`id`, `rpg_room`.`name`, `rpg_room`.`description`, `rpg_room`.`neighbors`, `rpg_room`.`exits`, `rpg_room`.`items` FROM `rpg_room` LIMIT 21; args=()
[19/Mar/2015 10:16:39] DEBUG [django.db.backends:91] (0.000) SELECT `rpg_room`.`id`, `rpg_room`.`name`, `rpg_room`.`description`, `rpg_room`.`neighbors`, `rpg_room`.`exits`, `rpg_room`.`items` FROM `rpg_room` LIMIT 21; args=()
[19/Mar/2015 10:16:39] DEBUG [django.db.backends:91] (0.000) SELECT `rpg_room`.`id`, `rpg_room`.`name`, `rpg_room`.`description`, `rpg_room`.`neighbors`, `rpg_room`.`exits`, `rpg_room`.`items` FROM `rpg_room` LIMIT 21; args=()
[19/Mar/2015 10:16:56] DEBUG [django.db.backends:91] (0.000) SET SQL_AUTO_IS_NULL = 0; args=None
[19/Mar/2015 10:16:56] DEBUG [django.db.backends:91] (0.000) SHOW TABLES; args=None
[19/Mar/2015 10:16:56] DEBUG [django.db.backends:91] (0.000) SELECT `django_migrations`.`app`, `django_migrations`.`name` FROM `django_migrations`; args=()
[19/Mar/2015 10:16:57] ERROR [django.request:231] Internal Server Error: /home2/
Traceback (most recent call last):
  File "/Users/jcook/.virtualenvs/default/lib/python2.7/site-packages/django/core/handlers/base.py", line 111, in get_response
    response = wrapped_callback(request, *callback_args, **callback_kwargs)
  File "/Users/jcook/Repos/site3/game/views.py", line 25, in home2
    return render(request, home2.html, context)
AttributeError: 'function' object has no attribute 'html'
[19/Mar/2015 10:16:57] DEBUG [django.db.backends:91] (0.000) SET SQL_AUTO_IS_NULL = 0; args=None
[19/Mar/2015 10:16:57] DEBUG [django.db.backends:91] (0.000) SELECT `rpg_room`.`id`, `rpg_room`.`name`, `rpg_room`.`description`, `rpg_room`.`neighbors`, `rpg_room`.`exits`, `rpg_room`.`items` FROM `rpg_room` LIMIT 21; args=()
[19/Mar/2015 10:16:57] DEBUG [django.db.backends:91] (0.000) SELECT `rpg_room`.`id`, `rpg_room`.`name`, `rpg_room`.`description`, `rpg_room`.`neighbors`, `rpg_room`.`exits`, `rpg_room`.`items` FROM `rpg_room` LIMIT 21; args=()
[19/Mar/2015 10:16:57] DEBUG [django.db.backends:91] (0.000) SELECT `rpg_room`.`id`, `rpg_room`.`name`, `rpg_room`.`description`, `rpg_room`.`neighbors`, `rpg_room`.`exits`, `rpg_room`.`items` FROM `rpg_room` LIMIT 21; args=()
[19/Mar/2015 10:17:41] DEBUG [django.db.backends:91] (0.000) SET SQL_AUTO_IS_NULL = 0; args=None
[19/Mar/2015 10:17:41] DEBUG [django.db.backends:91] (0.000) SHOW TABLES; args=None
[19/Mar/2015 10:17:41] DEBUG [django.db.backends:91] (0.000) SELECT `django_migrations`.`app`, `django_migrations`.`name` FROM `django_migrations`; args=()
[19/Mar/2015 10:18:41] ERROR [django.request:231] Internal Server Error: /home2/
Traceback (most recent call last):
  File "/Users/jcook/.virtualenvs/default/lib/python2.7/site-packages/django/core/handlers/base.py", line 111, in get_response
    response = wrapped_callback(request, *callback_args, **callback_kwargs)
  File "/Users/jcook/Repos/site3/game/views.py", line 25, in home2
    return render(request, game/home2.html, context)
NameError: global name 'game' is not defined
[19/Mar/2015 10:18:41] DEBUG [django.db.backends:91] (0.000) SET SQL_AUTO_IS_NULL = 0; args=None
[19/Mar/2015 10:18:41] DEBUG [django.db.backends:91] (0.000) SELECT `rpg_room`.`id`, `rpg_room`.`name`, `rpg_room`.`description`, `rpg_room`.`neighbors`, `rpg_room`.`exits`, `rpg_room`.`items` FROM `rpg_room` LIMIT 21; args=()
[19/Mar/2015 10:18:41] DEBUG [django.db.backends:91] (0.000) SELECT `rpg_room`.`id`, `rpg_room`.`name`, `rpg_room`.`description`, `rpg_room`.`neighbors`, `rpg_room`.`exits`, `rpg_room`.`items` FROM `rpg_room` LIMIT 21; args=()
[19/Mar/2015 10:18:41] DEBUG [django.db.backends:91] (0.000) SELECT `rpg_room`.`id`, `rpg_room`.`name`, `rpg_room`.`description`, `rpg_room`.`neighbors`, `rpg_room`.`exits`, `rpg_room`.`items` FROM `rpg_room` LIMIT 21; args=()
[19/Mar/2015 10:19:43] ERROR [django.request:231] Internal Server Error: /home2/
Traceback (most recent call last):
  File "/Users/jcook/.virtualenvs/default/lib/python2.7/site-packages/django/core/handlers/base.py", line 111, in get_response
    response = wrapped_callback(request, *callback_args, **callback_kwargs)
  File "/Users/jcook/Repos/site3/game/views.py", line 25, in home2
    return render(request, game/home2.html, context)
NameError: global name 'game' is not defined
[19/Mar/2015 10:19:44] DEBUG [django.db.backends:91] (0.000) SET SQL_AUTO_IS_NULL = 0; args=None
[19/Mar/2015 10:19:44] DEBUG [django.db.backends:91] (0.000) SELECT `rpg_room`.`id`, `rpg_room`.`name`, `rpg_room`.`description`, `rpg_room`.`neighbors`, `rpg_room`.`exits`, `rpg_room`.`items` FROM `rpg_room` LIMIT 21; args=()
[19/Mar/2015 10:19:44] DEBUG [django.db.backends:91] (0.000) SELECT `rpg_room`.`id`, `rpg_room`.`name`, `rpg_room`.`description`, `rpg_room`.`neighbors`, `rpg_room`.`exits`, `rpg_room`.`items` FROM `rpg_room` LIMIT 21; args=()
[19/Mar/2015 10:19:44] DEBUG [django.db.backends:91] (0.000) SELECT `rpg_room`.`id`, `rpg_room`.`name`, `rpg_room`.`description`, `rpg_room`.`neighbors`, `rpg_room`.`exits`, `rpg_room`.`items` FROM `rpg_room` LIMIT 21; args=()
[19/Mar/2015 10:19:47] DEBUG [django.db.backends:91] (0.001) SET SQL_AUTO_IS_NULL = 0; args=None
[19/Mar/2015 10:19:47] DEBUG [django.db.backends:91] (0.001) SHOW TABLES; args=None
[19/Mar/2015 10:19:47] DEBUG [django.db.backends:91] (0.002) SELECT `django_migrations`.`app`, `django_migrations`.`name` FROM `django_migrations`; args=()
[19/Mar/2015 10:19:50] ERROR [django.request:231] Internal Server Error: /home2/
Traceback (most recent call last):
  File "/Users/jcook/.virtualenvs/default/lib/python2.7/site-packages/django/core/handlers/base.py", line 111, in get_response
    response = wrapped_callback(request, *callback_args, **callback_kwargs)
  File "/Users/jcook/Repos/site3/game/views.py", line 25, in home2
    return render(request, home2.html, context)
AttributeError: 'function' object has no attribute 'html'
[19/Mar/2015 10:19:50] DEBUG [django.db.backends:91] (0.000) SET SQL_AUTO_IS_NULL = 0; args=None
[19/Mar/2015 10:19:50] DEBUG [django.db.backends:91] (0.000) SELECT `rpg_room`.`id`, `rpg_room`.`name`, `rpg_room`.`description`, `rpg_room`.`neighbors`, `rpg_room`.`exits`, `rpg_room`.`items` FROM `rpg_room` LIMIT 21; args=()
[19/Mar/2015 10:19:50] DEBUG [django.db.backends:91] (0.000) SELECT `rpg_room`.`id`, `rpg_room`.`name`, `rpg_room`.`description`, `rpg_room`.`neighbors`, `rpg_room`.`exits`, `rpg_room`.`items` FROM `rpg_room` LIMIT 21; args=()
[19/Mar/2015 10:19:50] DEBUG [django.db.backends:91] (0.000) SELECT `rpg_room`.`id`, `rpg_room`.`name`, `rpg_room`.`description`, `rpg_room`.`neighbors`, `rpg_room`.`exits`, `rpg_room`.`items` FROM `rpg_room` LIMIT 21; args=()
[19/Mar/2015 10:21:52] ERROR [django.request:231] Internal Server Error: /home2/
Traceback (most recent call last):
  File "/Users/jcook/.virtualenvs/default/lib/python2.7/site-packages/django/core/handlers/base.py", line 111, in get_response
    response = wrapped_callback(request, *callback_args, **callback_kwargs)
  File "/Users/jcook/Repos/site3/game/views.py", line 25, in home2
    return render(request, home2.html, context)
AttributeError: 'function' object has no attribute 'html'
[19/Mar/2015 10:21:52] DEBUG [django.db.backends:91] (0.000) SET SQL_AUTO_IS_NULL = 0; args=None
[19/Mar/2015 10:21:52] DEBUG [django.db.backends:91] (0.000) SELECT `rpg_room`.`id`, `rpg_room`.`name`, `rpg_room`.`description`, `rpg_room`.`neighbors`, `rpg_room`.`exits`, `rpg_room`.`items` FROM `rpg_room` LIMIT 21; args=()
[19/Mar/2015 10:21:52] DEBUG [django.db.backends:91] (0.000) SELECT `rpg_room`.`id`, `rpg_room`.`name`, `rpg_room`.`description`, `rpg_room`.`neighbors`, `rpg_room`.`exits`, `rpg_room`.`items` FROM `rpg_room` LIMIT 21; args=()
[19/Mar/2015 10:21:52] DEBUG [django.db.backends:91] (0.000) SELECT `rpg_room`.`id`, `rpg_room`.`name`, `rpg_room`.`description`, `rpg_room`.`neighbors`, `rpg_room`.`exits`, `rpg_room`.`items` FROM `rpg_room` LIMIT 21; args=()
[19/Mar/2015 10:21:53] DEBUG [django.db.backends:91] (0.000) SET SQL_AUTO_IS_NULL = 0; args=None
[19/Mar/2015 10:21:53] DEBUG [django.db.backends:91] (0.000) SHOW TABLES; args=None
[19/Mar/2015 10:21:53] DEBUG [django.db.backends:91] (0.000) SELECT `django_migrations`.`app`, `django_migrations`.`name` FROM `django_migrations`; args=()
[19/Mar/2015 10:22:24] ERROR [django.request:231] Internal Server Error: /home2/
Traceback (most recent call last):
  File "/Users/jcook/.virtualenvs/default/lib/python2.7/site-packages/django/core/handlers/base.py", line 111, in get_response
    response = wrapped_callback(request, *callback_args, **callback_kwargs)
  File "/Users/jcook/Repos/site3/game/views.py", line 26, in home2
    return render(request, template, context)
  File "/Users/jcook/.virtualenvs/default/lib/python2.7/site-packages/django/shortcuts.py", line 50, in render
    return HttpResponse(loader.render_to_string(*args, **kwargs),
  File "/Users/jcook/.virtualenvs/default/lib/python2.7/site-packages/django/template/loader.py", line 170, in render_to_string
    t = get_template(template_name, dirs)
  File "/Users/jcook/.virtualenvs/default/lib/python2.7/site-packages/django/template/loader.py", line 144, in get_template
    template, origin = find_template(template_name, dirs)
  File "/Users/jcook/.virtualenvs/default/lib/python2.7/site-packages/django/template/loader.py", line 136, in find_template
    raise TemplateDoesNotExist(name)
TemplateDoesNotExist: <module 'django.template' from '/Users/jcook/.virtualenvs/default/lib/python2.7/site-packages/django/template/__init__.pyc'>
[19/Mar/2015 10:22:24] DEBUG [django.db.backends:91] (0.000) SET SQL_AUTO_IS_NULL = 0; args=None
[19/Mar/2015 10:22:24] DEBUG [django.db.backends:91] (0.000) SELECT `rpg_room`.`id`, `rpg_room`.`name`, `rpg_room`.`description`, `rpg_room`.`neighbors`, `rpg_room`.`exits`, `rpg_room`.`items` FROM `rpg_room` LIMIT 21; args=()
[19/Mar/2015 10:22:24] DEBUG [django.db.backends:91] (0.000) SELECT `rpg_room`.`id`, `rpg_room`.`name`, `rpg_room`.`description`, `rpg_room`.`neighbors`, `rpg_room`.`exits`, `rpg_room`.`items` FROM `rpg_room` LIMIT 21; args=()
[19/Mar/2015 10:22:24] DEBUG [django.db.backends:91] (0.000) SELECT `rpg_room`.`id`, `rpg_room`.`name`, `rpg_room`.`description`, `rpg_room`.`neighbors`, `rpg_room`.`exits`, `rpg_room`.`items` FROM `rpg_room` LIMIT 21; args=()
[19/Mar/2015 10:22:24] DEBUG [django.db.backends:91] (0.000) SELECT `rpg_room`.`id`, `rpg_room`.`name`, `rpg_room`.`description`, `rpg_room`.`neighbors`, `rpg_room`.`exits`, `rpg_room`.`items` FROM `rpg_room` LIMIT 21; args=()
[19/Mar/2015 10:22:24] DEBUG [django.db.backends:91] (0.000) SELECT `rpg_room`.`id`, `rpg_room`.`name`, `rpg_room`.`description`, `rpg_room`.`neighbors`, `rpg_room`.`exits`, `rpg_room`.`items` FROM `rpg_room` LIMIT 21; args=()
[19/Mar/2015 10:22:24] DEBUG [django.db.backends:91] (0.000) SELECT `rpg_room`.`id`, `rpg_room`.`name`, `rpg_room`.`description`, `rpg_room`.`neighbors`, `rpg_room`.`exits`, `rpg_room`.`items` FROM `rpg_room` LIMIT 21; args=()
[19/Mar/2015 10:22:24] DEBUG [django.db.backends:91] (0.000) SELECT `rpg_room`.`id`, `rpg_room`.`name`, `rpg_room`.`description`, `rpg_room`.`neighbors`, `rpg_room`.`exits`, `rpg_room`.`items` FROM `rpg_room` LIMIT 21; args=()
[19/Mar/2015 10:22:24] DEBUG [django.db.backends:91] (0.000) SELECT `rpg_room`.`id`, `rpg_room`.`name`, `rpg_room`.`description`, `rpg_room`.`neighbors`, `rpg_room`.`exits`, `rpg_room`.`items` FROM `rpg_room` LIMIT 21; args=()
[19/Mar/2015 10:23:15] DEBUG [django.db.backends:91] (0.000) SET SQL_AUTO_IS_NULL = 0; args=None
[19/Mar/2015 10:23:15] DEBUG [django.db.backends:91] (0.000) SHOW TABLES; args=None
[19/Mar/2015 10:23:15] DEBUG [django.db.backends:91] (0.000) SELECT `django_migrations`.`app`, `django_migrations`.`name` FROM `django_migrations`; args=()
[19/Mar/2015 10:23:16] ERROR [django.request:231] Internal Server Error: /home2/
Traceback (most recent call last):
  File "/Users/jcook/.virtualenvs/default/lib/python2.7/site-packages/django/core/handlers/base.py", line 111, in get_response
    response = wrapped_callback(request, *callback_args, **callback_kwargs)
  File "/Users/jcook/Repos/site3/game/views.py", line 25, in home2
    return render(request, home2.html, context)
AttributeError: 'function' object has no attribute 'html'
[19/Mar/2015 10:23:16] DEBUG [django.db.backends:91] (0.000) SET SQL_AUTO_IS_NULL = 0; args=None
[19/Mar/2015 10:23:16] DEBUG [django.db.backends:91] (0.001) SELECT `rpg_room`.`id`, `rpg_room`.`name`, `rpg_room`.`description`, `rpg_room`.`neighbors`, `rpg_room`.`exits`, `rpg_room`.`items` FROM `rpg_room` LIMIT 21; args=()
[19/Mar/2015 10:23:16] DEBUG [django.db.backends:91] (0.001) SELECT `rpg_room`.`id`, `rpg_room`.`name`, `rpg_room`.`description`, `rpg_room`.`neighbors`, `rpg_room`.`exits`, `rpg_room`.`items` FROM `rpg_room` LIMIT 21; args=()
[19/Mar/2015 10:23:16] DEBUG [django.db.backends:91] (0.000) SELECT `rpg_room`.`id`, `rpg_room`.`name`, `rpg_room`.`description`, `rpg_room`.`neighbors`, `rpg_room`.`exits`, `rpg_room`.`items` FROM `rpg_room` LIMIT 21; args=()
[19/Mar/2015 10:24:47] DEBUG [django.db.backends:91] (0.000) SET SQL_AUTO_IS_NULL = 0; args=None
[19/Mar/2015 10:24:47] DEBUG [django.db.backends:91] (0.000) SHOW TABLES; args=None
[19/Mar/2015 10:24:47] DEBUG [django.db.backends:91] (0.000) SELECT `django_migrations`.`app`, `django_migrations`.`name` FROM `django_migrations`; args=()
[19/Mar/2015 10:24:49] ERROR [django.request:231] Internal Server Error: /home2/
Traceback (most recent call last):
  File "/Users/jcook/.virtualenvs/default/lib/python2.7/site-packages/django/core/handlers/base.py", line 111, in get_response
    response = wrapped_callback(request, *callback_args, **callback_kwargs)
  File "/Users/jcook/Repos/site3/game/views.py", line 15, in home2
    return render(request, home2.html, context)
AttributeError: 'function' object has no attribute 'html'
[19/Mar/2015 10:24:49] DEBUG [django.db.backends:91] (0.000) SET SQL_AUTO_IS_NULL = 0; args=None
[19/Mar/2015 10:24:49] DEBUG [django.db.backends:91] (0.000) SELECT `rpg_room`.`id`, `rpg_room`.`name`, `rpg_room`.`description`, `rpg_room`.`neighbors`, `rpg_room`.`exits`, `rpg_room`.`items` FROM `rpg_room` LIMIT 21; args=()
[19/Mar/2015 10:24:49] DEBUG [django.db.backends:91] (0.000) SELECT `rpg_room`.`id`, `rpg_room`.`name`, `rpg_room`.`description`, `rpg_room`.`neighbors`, `rpg_room`.`exits`, `rpg_room`.`items` FROM `rpg_room` LIMIT 21; args=()
[19/Mar/2015 10:24:49] DEBUG [django.db.backends:91] (0.000) SELECT `rpg_room`.`id`, `rpg_room`.`name`, `rpg_room`.`description`, `rpg_room`.`neighbors`, `rpg_room`.`exits`, `rpg_room`.`items` FROM `rpg_room` LIMIT 21; args=()
[19/Mar/2015 10:28:10] DEBUG [django.db.backends:91] (0.000) SET SQL_AUTO_IS_NULL = 0; args=None
[19/Mar/2015 10:28:10] DEBUG [django.db.backends:91] (0.000) SHOW TABLES; args=None
[19/Mar/2015 10:28:10] DEBUG [django.db.backends:91] (0.000) SELECT `django_migrations`.`app`, `django_migrations`.`name` FROM `django_migrations`; args=()
[19/Mar/2015 10:28:40] ERROR [django.request:231] Internal Server Error: /home2/
Traceback (most recent call last):
  File "/Users/jcook/.virtualenvs/default/lib/python2.7/site-packages/django/core/handlers/base.py", line 111, in get_response
    response = wrapped_callback(request, *callback_args, **callback_kwargs)
  File "/Users/jcook/Repos/site3/game/views.py", line 14, in home2
    return render(request, home2.html, context)
AttributeError: 'function' object has no attribute 'html'
[19/Mar/2015 10:28:40] DEBUG [django.db.backends:91] (0.000) SET SQL_AUTO_IS_NULL = 0; args=None
[19/Mar/2015 10:28:40] DEBUG [django.db.backends:91] (0.000) SELECT `rpg_room`.`id`, `rpg_room`.`name`, `rpg_room`.`description`, `rpg_room`.`neighbors`, `rpg_room`.`exits`, `rpg_room`.`items` FROM `rpg_room` LIMIT 21; args=()
[19/Mar/2015 10:28:40] DEBUG [django.db.backends:91] (0.000) SELECT `rpg_room`.`id`, `rpg_room`.`name`, `rpg_room`.`description`, `rpg_room`.`neighbors`, `rpg_room`.`exits`, `rpg_room`.`items` FROM `rpg_room` LIMIT 21; args=()
[19/Mar/2015 10:28:40] DEBUG [django.db.backends:91] (0.000) SELECT `rpg_room`.`id`, `rpg_room`.`name`, `rpg_room`.`description`, `rpg_room`.`neighbors`, `rpg_room`.`exits`, `rpg_room`.`items` FROM `rpg_room` LIMIT 21; args=()
[19/Mar/2015 10:30:08] DEBUG [django.db.backends:91] (0.000) SET SQL_AUTO_IS_NULL = 0; args=None
[19/Mar/2015 10:30:08] DEBUG [django.db.backends:91] (0.000) SHOW TABLES; args=None
[19/Mar/2015 10:30:08] DEBUG [django.db.backends:91] (0.000) SELECT `django_migrations`.`app`, `django_migrations`.`name` FROM `django_migrations`; args=()
[19/Mar/2015 10:30:09] WARNING [django.request:143] Not Found: /home2/css/style.css
[19/Mar/2015 10:44:01] DEBUG [django.db.backends:91] (0.000) SET SQL_AUTO_IS_NULL = 0; args=None
[19/Mar/2015 10:44:01] DEBUG [django.db.backends:91] (0.000) SHOW TABLES; args=None
[19/Mar/2015 10:44:01] DEBUG [django.db.backends:91] (0.000) SELECT `django_migrations`.`app`, `django_migrations`.`name` FROM `django_migrations`; args=()
[19/Mar/2015 10:52:42] ERROR [django.request:231] Internal Server Error: /home2/
Traceback (most recent call last):
  File "/Users/jcook/.virtualenvs/default/lib/python2.7/site-packages/django/core/handlers/base.py", line 98, in get_response
    resolver_match = resolver.resolve(request.path_info)
  File "/Users/jcook/.virtualenvs/default/lib/python2.7/site-packages/django/core/urlresolvers.py", line 343, in resolve
    for pattern in self.url_patterns:
  File "/Users/jcook/.virtualenvs/default/lib/python2.7/site-packages/django/core/urlresolvers.py", line 372, in url_patterns
    patterns = getattr(self.urlconf_module, "urlpatterns", self.urlconf_module)
  File "/Users/jcook/.virtualenvs/default/lib/python2.7/site-packages/django/core/urlresolvers.py", line 366, in urlconf_module
    self._urlconf_module = import_module(self.urlconf_name)
  File "/System/Library/Frameworks/Python.framework/Versions/2.7/lib/python2.7/importlib/__init__.py", line 37, in import_module
    __import__(name)
  File "/Users/jcook/Repos/site3/game/urls.py", line 12, in <module>
    url(r'^rpg/', include('rpg.urls', namespace="rpg")),
  File "/Users/jcook/.virtualenvs/default/lib/python2.7/site-packages/django/conf/urls/__init__.py", line 28, in include
    urlconf_module = import_module(urlconf_module)
  File "/System/Library/Frameworks/Python.framework/Versions/2.7/lib/python2.7/importlib/__init__.py", line 37, in import_module
    __import__(name)
  File "/Users/jcook/Repos/site3/rpg/urls.py", line 6, in <module>
    url(r'^$', views.index, name='index'),
AttributeError: 'module' object has no attribute 'index'
[19/Mar/2015 10:53:29] ERROR [django.request:231] Internal Server Error: /rpg
Traceback (most recent call last):
  File "/Users/jcook/.virtualenvs/default/lib/python2.7/site-packages/django/core/handlers/base.py", line 87, in get_response
    response = middleware_method(request)
  File "/Users/jcook/.virtualenvs/default/lib/python2.7/site-packages/django/middleware/common.py", line 72, in process_request
    if (not urlresolvers.is_valid_path(request.path_info, urlconf) and
  File "/Users/jcook/.virtualenvs/default/lib/python2.7/site-packages/django/core/urlresolvers.py", line 619, in is_valid_path
    resolve(path, urlconf)
  File "/Users/jcook/.virtualenvs/default/lib/python2.7/site-packages/django/core/urlresolvers.py", line 494, in resolve
    return get_resolver(urlconf).resolve(path)
  File "/Users/jcook/.virtualenvs/default/lib/python2.7/site-packages/django/core/urlresolvers.py", line 343, in resolve
    for pattern in self.url_patterns:
  File "/Users/jcook/.virtualenvs/default/lib/python2.7/site-packages/django/core/urlresolvers.py", line 372, in url_patterns
    patterns = getattr(self.urlconf_module, "urlpatterns", self.urlconf_module)
  File "/Users/jcook/.virtualenvs/default/lib/python2.7/site-packages/django/core/urlresolvers.py", line 366, in urlconf_module
    self._urlconf_module = import_module(self.urlconf_name)
  File "/System/Library/Frameworks/Python.framework/Versions/2.7/lib/python2.7/importlib/__init__.py", line 37, in import_module
    __import__(name)
  File "/Users/jcook/Repos/site3/game/urls.py", line 12, in <module>
    url(r'^rpg/', include('rpg.urls', namespace="rpg")),
  File "/Users/jcook/.virtualenvs/default/lib/python2.7/site-packages/django/conf/urls/__init__.py", line 28, in include
    urlconf_module = import_module(urlconf_module)
  File "/System/Library/Frameworks/Python.framework/Versions/2.7/lib/python2.7/importlib/__init__.py", line 37, in import_module
    __import__(name)
  File "/Users/jcook/Repos/site3/rpg/urls.py", line 6, in <module>
    url(r'^$', views.index, name='index'),
AttributeError: 'module' object has no attribute 'index'
[19/Mar/2015 10:53:38] ERROR [django.request:231] Internal Server Error: /rpg/home2
Traceback (most recent call last):
  File "/Users/jcook/.virtualenvs/default/lib/python2.7/site-packages/django/core/handlers/base.py", line 87, in get_response
    response = middleware_method(request)
  File "/Users/jcook/.virtualenvs/default/lib/python2.7/site-packages/django/middleware/common.py", line 72, in process_request
    if (not urlresolvers.is_valid_path(request.path_info, urlconf) and
  File "/Users/jcook/.virtualenvs/default/lib/python2.7/site-packages/django/core/urlresolvers.py", line 619, in is_valid_path
    resolve(path, urlconf)
  File "/Users/jcook/.virtualenvs/default/lib/python2.7/site-packages/django/core/urlresolvers.py", line 494, in resolve
    return get_resolver(urlconf).resolve(path)
  File "/Users/jcook/.virtualenvs/default/lib/python2.7/site-packages/django/core/urlresolvers.py", line 343, in resolve
    for pattern in self.url_patterns:
  File "/Users/jcook/.virtualenvs/default/lib/python2.7/site-packages/django/core/urlresolvers.py", line 372, in url_patterns
    patterns = getattr(self.urlconf_module, "urlpatterns", self.urlconf_module)
  File "/Users/jcook/.virtualenvs/default/lib/python2.7/site-packages/django/core/urlresolvers.py", line 366, in urlconf_module
    self._urlconf_module = import_module(self.urlconf_name)
  File "/System/Library/Frameworks/Python.framework/Versions/2.7/lib/python2.7/importlib/__init__.py", line 37, in import_module
    __import__(name)
  File "/Users/jcook/Repos/site3/game/urls.py", line 12, in <module>
    url(r'^rpg/', include('rpg.urls', namespace="rpg")),
  File "/Users/jcook/.virtualenvs/default/lib/python2.7/site-packages/django/conf/urls/__init__.py", line 28, in include
    urlconf_module = import_module(urlconf_module)
  File "/System/Library/Frameworks/Python.framework/Versions/2.7/lib/python2.7/importlib/__init__.py", line 37, in import_module
    __import__(name)
  File "/Users/jcook/Repos/site3/rpg/urls.py", line 6, in <module>
    url(r'^$', views.index, name='index'),
AttributeError: 'module' object has no attribute 'index'
[19/Mar/2015 10:53:48] ERROR [django.request:231] Internal Server Error: /rpg/home2.html
Traceback (most recent call last):
  File "/Users/jcook/.virtualenvs/default/lib/python2.7/site-packages/django/core/handlers/base.py", line 87, in get_response
    response = middleware_method(request)
  File "/Users/jcook/.virtualenvs/default/lib/python2.7/site-packages/django/middleware/common.py", line 72, in process_request
    if (not urlresolvers.is_valid_path(request.path_info, urlconf) and
  File "/Users/jcook/.virtualenvs/default/lib/python2.7/site-packages/django/core/urlresolvers.py", line 619, in is_valid_path
    resolve(path, urlconf)
  File "/Users/jcook/.virtualenvs/default/lib/python2.7/site-packages/django/core/urlresolvers.py", line 494, in resolve
    return get_resolver(urlconf).resolve(path)
  File "/Users/jcook/.virtualenvs/default/lib/python2.7/site-packages/django/core/urlresolvers.py", line 343, in resolve
    for pattern in self.url_patterns:
  File "/Users/jcook/.virtualenvs/default/lib/python2.7/site-packages/django/core/urlresolvers.py", line 372, in url_patterns
    patterns = getattr(self.urlconf_module, "urlpatterns", self.urlconf_module)
  File "/Users/jcook/.virtualenvs/default/lib/python2.7/site-packages/django/core/urlresolvers.py", line 366, in urlconf_module
    self._urlconf_module = import_module(self.urlconf_name)
  File "/System/Library/Frameworks/Python.framework/Versions/2.7/lib/python2.7/importlib/__init__.py", line 37, in import_module
    __import__(name)
  File "/Users/jcook/Repos/site3/game/urls.py", line 12, in <module>
    url(r'^rpg/', include('rpg.urls', namespace="rpg")),
  File "/Users/jcook/.virtualenvs/default/lib/python2.7/site-packages/django/conf/urls/__init__.py", line 28, in include
    urlconf_module = import_module(urlconf_module)
  File "/System/Library/Frameworks/Python.framework/Versions/2.7/lib/python2.7/importlib/__init__.py", line 37, in import_module
    __import__(name)
  File "/Users/jcook/Repos/site3/rpg/urls.py", line 6, in <module>
    url(r'^$', views.index, name='index'),
AttributeError: 'module' object has no attribute 'index'
[19/Mar/2015 10:54:30] WARNING [django.request:143] Not Found: /rpg/home2.html
[19/Mar/2015 10:54:39] WARNING [django.request:143] Not Found: /home2/css/style.css
[19/Mar/2015 11:15:46] WARNING [django.request:143] Not Found: /home2/css/style.css
[19/Mar/2015 14:11:00] WARNING [django.request:143] Not Found: /home2/css/style.css
[19/Mar/2015 14:11:06] WARNING [django.request:143] Not Found: /home2/css/style.css
[19/Mar/2015 14:11:08] WARNING [django.request:143] Not Found: /home2/css/style.css
